[ERROR] [UID:2795][1320736] wsgiAppHandler pApp->start_response() return NULL.
Traceback (most recent call last):
  File "/home/inlinkff/virtualenv/linkedin-crm/3.11/lib64/python3.11/site-packages/sqlalchemy/engine/base.py", line 146, in __init__
    self._dbapi_connection = engine.raw_connection()
                             ^^^^^^^^^^^^^^^^^^^^^^^
  File "/home/inlinkff/virtualenv/linkedin-crm/3.11/lib64/python3.11/site-packages/sqlalchemy/engine/base.py", line 3298, in raw_connection
    return self.pool.connect()
           ^^^^^^^^^^^^^^^^^^^
  File "/home/inlinkff/virtualenv/linkedin-crm/3.11/lib64/python3.11/site-packages/sqlalchemy/pool/base.py", line 449, in connect
    return _ConnectionFairy._checkout(self)
           ^^^^^^^^^^^^^^^^^^^^^^^^^^^^^^^^
  File "/home/inlinkff/virtualenv/linkedin-crm/3.11/lib64/python3.11/site-packages/sqlalchemy/pool/base.py", line 1264, in _checkout
    fairy = _ConnectionRecord.checkout(pool)
            ^^^^^^^^^^^^^^^^^^^^^^^^^^^^^^^^
  File "/home/inlinkff/virtualenv/linkedin-crm/3.11/lib64/python3.11/site-packages/sqlalchemy/pool/base.py", line 713, in checkout
    rec = pool._do_get()
          ^^^^^^^^^^^^^^
  File "/home/inlinkff/virtualenv/linkedin-crm/3.11/lib64/python3.11/site-packages/sqlalchemy/pool/impl.py", line 179, in _do_get
    with util.safe_reraise():
  File "/home/inlinkff/virtualenv/linkedin-crm/3.11/lib64/python3.11/site-packages/sqlalchemy/util/langhelpers.py", line 146, in __exit__
    raise exc_value.with_traceback(exc_tb)
  File "/home/inlinkff/virtualenv/linkedin-crm/3.11/lib64/python3.11/site-packages/sqlalchemy/pool/impl.py", line 177, in _do_get
    return self._create_connection()
           ^^^^^^^^^^^^^^^^^^^^^^^^^
  File "/home/inlinkff/virtualenv/linkedin-crm/3.11/lib64/python3.11/site-packages/sqlalchemy/pool/base.py", line 390, in _create_connection
    return _ConnectionRecord(self)
           ^^^^^^^^^^^^^^^^^^^^^^^
  File "/home/inlinkff/virtualenv/linkedin-crm/3.11/lib64/python3.11/site-packages/sqlalchemy/pool/base.py", line 675, in __init__
    self.__connect()
  File "/home/inlinkff/virtualenv/linkedin-crm/3.11/lib64/python3.11/site-packages/sqlalchemy/pool/base.py", line 901, in __connect
    with util.safe_reraise():
  File "/home/inlinkff/virtualenv/linkedin-crm/3.11/lib64/python3.11/site-packages/sqlalchemy/util/langhelpers.py", line 146, in __exit__
    raise exc_value.with_traceback(exc_tb)
  File "/home/inlinkff/virtualenv/linkedin-crm/3.11/lib64/python3.11/site-packages/sqlalchemy/pool/base.py", line 897, in __connect
    self.dbapi_connection = connection = pool._invoke_creator(self)
                                         ^^^^^^^^^^^^^^^^^^^^^^^^^^
  File "/home/inlinkff/virtualenv/linkedin-crm/3.11/lib64/python3.11/site-packages/sqlalchemy/engine/create.py", line 646, in connect
    return dialect.connect(*cargs, **cparams)
           ^^^^^^^^^^^^^^^^^^^^^^^^^^^^^^^^^^
  File "/home/inlinkff/virtualenv/linkedin-crm/3.11/lib64/python3.11/site-packages/sqlalchemy/engine/default.py", line 622, in connect
    return self.loaded_dbapi.connect(*cargs, **cparams)
           ^^^^^^^^^^^^^^^^^^^^^^^^^^^^^^^^^^^^^^^^^^^^
  File "/home/inlinkff/virtualenv/linkedin-crm/3.11/lib/python3.11/site-packages/pymysql/connections.py", line 358, in __init__
    self.connect()
  File "/home/inlinkff/virtualenv/linkedin-crm/3.11/lib/python3.11/site-packages/pymysql/connections.py", line 664, in connect
    self._request_authentication()
  File "/home/inlinkff/virtualenv/linkedin-crm/3.11/lib/python3.11/site-packages/pymysql/connections.py", line 954, in _request_authentication
    auth_packet = self._read_packet()
                  ^^^^^^^^^^^^^^^^^^^
  File "/home/inlinkff/virtualenv/linkedin-crm/3.11/lib/python3.11/site-packages/pymysql/connections.py", line 772, in _read_packet
    packet.raise_for_error()
  File "/home/inlinkff/virtualenv/linkedin-crm/3.11/lib/python3.11/site-packages/pymysql/protocol.py", line 221, in raise_for_error
    err.raise_mysql_exception(self._data)
  File "/home/inlinkff/virtualenv/linkedin-crm/3.11/lib/python3.11/site-packages/pymysql/err.py", line 143, in raise_mysql_exception
    raise errorclass(errno, errval)
pymysql.err.OperationalError: (1045, "Access denied for user 'root'@'localhost' (using password: NO)")

The above exception was the direct cause of the following exception:

Traceback (most recent call last):
  File "/home/inlinkff/virtualenv/linkedin-crm/3.11/lib/python3.11/site-packages/flask/app.py", line 2213, in __call__
    return self.wsgi_app(environ, start_response)
           ^^^^^^^^^^^^^^^^^^^^^^^^^^^^^^^^^^^^^^
  File "/home/inlinkff/virtualenv/linkedin-crm/3.11/lib/python3.11/site-packages/flask/app.py", line 2193, in wsgi_app
    response = self.handle_exception(e)
               ^^^^^^^^^^^^^^^^^^^^^^^^
  File "/home/inlinkff/virtualenv/linkedin-crm/3.11/lib/python3.11/site-packages/flask_cors/extension.py", line 176, in wrapped_function
    return cors_after_request(app.make_response(f(*args, **kwargs)))
                                                ^^^^^^^^^^^^^^^^^^
  File "/home/inlinkff/virtualenv/linkedin-crm/3.11/lib/python3.11/site-packages/flask/app.py", line 2190, in wsgi_app
    response = self.full_dispatch_request()
               ^^^^^^^^^^^^^^^^^^^^^^^^^^^^
  File "/home/inlinkff/virtualenv/linkedin-crm/3.11/lib/python3.11/site-packages/flask/app.py", line 1486, in full_dispatch_request
    rv = self.handle_user_exception(e)
         ^^^^^^^^^^^^^^^^^^^^^^^^^^^^^
  File "/home/inlinkff/virtualenv/linkedin-crm/3.11/lib/python3.11/site-packages/flask_cors/extension.py", line 176, in wrapped_function
    return cors_after_request(app.make_response(f(*args, **kwargs)))
                                                ^^^^^^^^^^^^^^^^^^
  File "/home/inlinkff/virtualenv/linkedin-crm/3.11/lib/python3.11/site-packages/flask/app.py", line 1484, in full_dispatch_request
    rv = self.dispatch_request()
         ^^^^^^^^^^^^^^^^^^^^^^^
  File "/home/inlinkff/virtualenv/linkedin-crm/3.11/lib/python3.11/site-packages/flask/app.py", line 1469, in dispatch_request
    return self.ensure_sync(self.view_functions[rule.endpoint])(**view_args)
           ^^^^^^^^^^^^^^^^^^^^^^^^^^^^^^^^^^^^^^^^^^^^^^^^^^^^^^^^^^^^^^^^^
  File "/home/inlinkff/linkedin-crm/app/controllers/auth.py", line 15, in login
    user = User.query.filter_by(email=form.email.data).first()
           ^^^^^^^^^^^^^^^^^^^^^^^^^^^^^^^^^^^^^^^^^^^^^^^^^^^
  File "/home/inlinkff/virtualenv/linkedin-crm/3.11/lib64/python3.11/site-packages/sqlalchemy/orm/query.py", line 2759, in first
    return self.limit(1)._iter().first()  # type: ignore
           ^^^^^^^^^^^^^^^^^^^^^
  File "/home/inlinkff/virtualenv/linkedin-crm/3.11/lib64/python3.11/site-packages/sqlalchemy/orm/query.py", line 2858, in _iter
    result: Union[ScalarResult[_T], Result[_T]] = self.session.execute(
                                                  ^^^^^^^^^^^^^^^^^^^^^
  File "/home/inlinkff/virtualenv/linkedin-crm/3.11/lib64/python3.11/site-packages/sqlalchemy/orm/session.py", line 2365, in execute
    return self._execute_internal(
           ^^^^^^^^^^^^^^^^^^^^^^^
  File "/home/inlinkff/virtualenv/linkedin-crm/3.11/lib64/python3.11/site-packages/sqlalchemy/orm/session.py", line 2241, in _execute_internal
    conn = self._connection_for_bind(bind)
           ^^^^^^^^^^^^^^^^^^^^^^^^^^^^^^^
  File "/home/inlinkff/virtualenv/linkedin-crm/3.11/lib64/python3.11/site-packages/sqlalchemy/orm/session.py", line 2110, in _connection_for_bind
    return trans._connection_for_bind(engine, execution_options)
           ^^^^^^^^^^^^^^^^^^^^^^^^^^^^^^^^^^^^^^^^^^^^^^^^^^^^^
  File "<string>", line 2, in _connection_for_bind
  File "/home/inlinkff/virtualenv/linkedin-crm/3.11/lib64/python3.11/site-packages/sqlalchemy/orm/state_changes.py", line 139, in _go
    ret_value = fn(self, *arg, **kw)
                ^^^^^^^^^^^^^^^^^^^^
  File "/home/inlinkff/virtualenv/linkedin-crm/3.11/lib64/python3.11/site-packages/sqlalchemy/orm/session.py", line 1189, in _connection_for_bind
    conn = bind.connect()
           ^^^^^^^^^^^^^^
  File "/home/inlinkff/virtualenv/linkedin-crm/3.11/lib64/python3.11/site-packages/sqlalchemy/engine/base.py", line 3274, in connect
    return self._connection_cls(self)
           ^^^^^^^^^^^^^^^^^^^^^^^^^^
  File "/home/inlinkff/virtualenv/linkedin-crm/3.11/lib64/python3.11/site-packages/sqlalchemy/engine/base.py", line 148, in __init__
    Connection._handle_dbapi_exception_noconnection(
  File "/home/inlinkff/virtualenv/linkedin-crm/3.11/lib64/python3.11/site-packages/sqlalchemy/engine/base.py", line 2439, in _handle_dbapi_exception_noconnection
    raise sqlalchemy_exception.with_traceback(exc_info[2]) from e
  File "/home/inlinkff/virtualenv/linkedin-crm/3.11/lib64/python3.11/site-packages/sqlalchemy/engine/base.py", line 146, in __init__
    self._dbapi_connection = engine.raw_connection()
                             ^^^^^^^^^^^^^^^^^^^^^^^
  File "/home/inlinkff/virtualenv/linkedin-crm/3.11/lib64/python3.11/site-packages/sqlalchemy/engine/base.py", line 3298, in raw_connection
    return self.pool.connect()
           ^^^^^^^^^^^^^^^^^^^
  File "/home/inlinkff/virtualenv/linkedin-crm/3.11/lib64/python3.11/site-packages/sqlalchemy/pool/base.py", line 449, in connect
    return _ConnectionFairy._checkout(self)
           ^^^^^^^^^^^^^^^^^^^^^^^^^^^^^^^^
  File "/home/inlinkff/virtualenv/linkedin-crm/3.11/lib64/python3.11/site-packages/sqlalchemy/pool/base.py", line 1264, in _checkout
    fairy = _ConnectionRecord.checkout(pool)
            ^^^^^^^^^^^^^^^^^^^^^^^^^^^^^^^^
  File "/home/inlinkff/virtualenv/linkedin-crm/3.11/lib64/python3.11/site-packages/sqlalchemy/pool/base.py", line 713, in checkout
    rec = pool._do_get()
          ^^^^^^^^^^^^^^
  File "/home/inlinkff/virtualenv/linkedin-crm/3.11/lib64/python3.11/site-packages/sqlalchemy/pool/impl.py", line 179, in _do_get
    with util.safe_reraise():
  File "/home/inlinkff/virtualenv/linkedin-crm/3.11/lib64/python3.11/site-packages/sqlalchemy/util/langhelpers.py", line 146, in __exit__
    raise exc_value.with_traceback(exc_tb)
  File "/home/inlinkff/virtualenv/linkedin-crm/3.11/lib64/python3.11/site-packages/sqlalchemy/pool/impl.py", line 177, in _do_get
    return self._create_connection()
           ^^^^^^^^^^^^^^^^^^^^^^^^^
  File "/home/inlinkff/virtualenv/linkedin-crm/3.11/lib64/python3.11/site-packages/sqlalchemy/pool/base.py", line 390, in _create_connection
    return _ConnectionRecord(self)
           ^^^^^^^^^^^^^^^^^^^^^^^
  File "/home/inlinkff/virtualenv/linkedin-crm/3.11/lib64/python3.11/site-packages/sqlalchemy/pool/base.py", line 675, in __init__
    self.__connect()
  File "/home/inlinkff/virtualenv/linkedin-crm/3.11/lib64/python3.11/site-packages/sqlalchemy/pool/base.py", line 901, in __connect
    with util.safe_reraise():
  File "/home/inlinkff/virtualenv/linkedin-crm/3.11/lib64/python3.11/site-packages/sqlalchemy/util/langhelpers.py", line 146, in __exit__
    raise exc_value.with_traceback(exc_tb)
  File "/home/inlinkff/virtualenv/linkedin-crm/3.11/lib64/python3.11/site-packages/sqlalchemy/pool/base.py", line 897, in __connect
    self.dbapi_connection = connection = pool._invoke_creator(self)
                                         ^^^^^^^^^^^^^^^^^^^^^^^^^^
  File "/home/inlinkff/virtualenv/linkedin-crm/3.11/lib64/python3.11/site-packages/sqlalchemy/engine/create.py", line 646, in connect
    return dialect.connect(*cargs, **cparams)
           ^^^^^^^^^^^^^^^^^^^^^^^^^^^^^^^^^^
  File "/home/inlinkff/virtualenv/linkedin-crm/3.11/lib64/python3.11/site-packages/sqlalchemy/engine/default.py", line 622, in connect
    return self.loaded_dbapi.connect(*cargs, **cparams)
           ^^^^^^^^^^^^^^^^^^^^^^^^^^^^^^^^^^^^^^^^^^^^
  File "/home/inlinkff/virtualenv/linkedin-crm/3.11/lib/python3.11/site-packages/pymysql/connections.py", line 358, in __init__
    self.connect()
  File "/home/inlinkff/virtualenv/linkedin-crm/3.11/lib/python3.11/site-packages/pymysql/connections.py", line 664, in connect
    self._request_authentication()
  File "/home/inlinkff/virtualenv/linkedin-crm/3.11/lib/python3.11/site-packages/pymysql/connections.py", line 954, in _request_authentication
    auth_packet = self._read_packet()
                  ^^^^^^^^^^^^^^^^^^^
  File "/home/inlinkff/virtualenv/linkedin-crm/3.11/lib/python3.11/site-packages/pymysql/connections.py", line 772, in _read_packet
    packet.raise_for_error()
  File "/home/inlinkff/virtualenv/linkedin-crm/3.11/lib/python3.11/site-packages/pymysql/protocol.py", line 221, in raise_for_error
    err.raise_mysql_exception(self._data)
  File "/home/inlinkff/virtualenv/linkedin-crm/3.11/lib/python3.11/site-packages/pymysql/err.py", line 143, in raise_mysql_exception
    raise errorclass(errno, errval)
sqlalchemy.exc.OperationalError: (pymysql.err.OperationalError) (1045, "Access denied for user 'root'@'localhost' (using password: NO)")
(Background on this error at: https://sqlalche.me/e/20/e3q8)
[2025-03-17 21:20:03,475] ERROR in app: Exception on /register [POST]
Traceback (most recent call last):
  File "/home/inlinkff/virtualenv/linkedin-crm/3.11/lib64/python3.11/site-packages/sqlalchemy/engine/base.py", line 1964, in _exec_single_context
    self.dialect.do_execute(
  File "/home/inlinkff/virtualenv/linkedin-crm/3.11/lib64/python3.11/site-packages/sqlalchemy/engine/default.py", line 942, in do_execute
    cursor.execute(statement, parameters)
  File "/home/inlinkff/virtualenv/linkedin-crm/3.11/lib/python3.11/site-packages/pymysql/cursors.py", line 153, in execute
    result = self._query(query)
             ^^^^^^^^^^^^^^^^^^
  File "/home/inlinkff/virtualenv/linkedin-crm/3.11/lib/python3.11/site-packages/pymysql/cursors.py", line 322, in _query
    conn.query(q)
  File "/home/inlinkff/virtualenv/linkedin-crm/3.11/lib/python3.11/site-packages/pymysql/connections.py", line 558, in query
    self._affected_rows = self._read_query_result(unbuffered=unbuffered)
                          ^^^^^^^^^^^^^^^^^^^^^^^^^^^^^^^^^^^^^^^^^^^^^^
  File "/home/inlinkff/virtualenv/linkedin-crm/3.11/lib/python3.11/site-packages/pymysql/connections.py", line 822, in _read_query_result
    result.read()
  File "/home/inlinkff/virtualenv/linkedin-crm/3.11/lib/python3.11/site-packages/pymysql/connections.py", line 1200, in read
    first_packet = self.connection._read_packet()
                   ^^^^^^^^^^^^^^^^^^^^^^^^^^^^^^
  File "/home/inlinkff/virtualenv/linkedin-crm/3.11/lib/python3.11/site-packages/pymysql/connections.py", line 772, in _read_packet
    packet.raise_for_error()
  File "/home/inlinkff/virtualenv/linkedin-crm/3.11/lib/python3.11/site-packages/pymysql/protocol.py", line 221, in raise_for_error
    err.raise_mysql_exception(self._data)
  File "/home/inlinkff/virtualenv/linkedin-crm/3.11/lib/python3.11/site-packages/pymysql/err.py", line 143, in raise_mysql_exception
    raise errorclass(errno, errval)
pymysql.err.ProgrammingError: (1146, "Table 'inlinkff_crm.users' doesn't exist")

The above exception was the direct cause of the following exception:

Traceback (most recent call last):
  File "/home/inlinkff/virtualenv/linkedin-crm/3.11/lib/python3.11/site-packages/flask/app.py", line 2190, in wsgi_app
    response = self.full_dispatch_request()
               ^^^^^^^^^^^^^^^^^^^^^^^^^^^^
  File "/home/inlinkff/virtualenv/linkedin-crm/3.11/lib/python3.11/site-packages/flask/app.py", line 1486, in full_dispatch_request
    rv = self.handle_user_exception(e)
         ^^^^^^^^^^^^^^^^^^^^^^^^^^^^^
  File "/home/inlinkff/virtualenv/linkedin-crm/3.11/lib/python3.11/site-packages/flask_cors/extension.py", line 176, in wrapped_function
    return cors_after_request(app.make_response(f(*args, **kwargs)))
                                                ^^^^^^^^^^^^^^^^^^
  File "/home/inlinkff/virtualenv/linkedin-crm/3.11/lib/python3.11/site-packages/flask/app.py", line 1484, in full_dispatch_request
    rv = self.dispatch_request()
         ^^^^^^^^^^^^^^^^^^^^^^^
  File "/home/inlinkff/virtualenv/linkedin-crm/3.11/lib/python3.11/site-packages/flask/app.py", line 1469, in dispatch_request
    return self.ensure_sync(self.view_functions[rule.endpoint])(**view_args)
           ^^^^^^^^^^^^^^^^^^^^^^^^^^^^^^^^^^^^^^^^^^^^^^^^^^^^^^^^^^^^^^^^^
  File "/home/inlinkff/linkedin-crm/app/controllers/auth.py", line 38, in register
    if form.validate_on_submit():
       ^^^^^^^^^^^^^^^^^^^^^^^^^
  File "/home/inlinkff/virtualenv/linkedin-crm/3.11/lib/python3.11/site-packages/flask_wtf/form.py", line 86, in validate_on_submit
    return self.is_submitted() and self.validate(extra_validators=extra_validators)
                                   ^^^^^^^^^^^^^^^^^^^^^^^^^^^^^^^^^^^^^^^^^^^^^^^^
  File "/home/inlinkff/virtualenv/linkedin-crm/3.11/lib/python3.11/site-packages/wtforms/form.py", line 330, in validate
    return super().validate(extra)
           ^^^^^^^^^^^^^^^^^^^^^^^
  File "/home/inlinkff/virtualenv/linkedin-crm/3.11/lib/python3.11/site-packages/wtforms/form.py", line 147, in validate
    if not field.validate(self, extra):
           ^^^^^^^^^^^^^^^^^^^^^^^^^^^
  File "/home/inlinkff/virtualenv/linkedin-crm/3.11/lib/python3.11/site-packages/wtforms/fields/core.py", line 234, in validate
    stop_validation = self._run_validation_chain(form, chain)
                      ^^^^^^^^^^^^^^^^^^^^^^^^^^^^^^^^^^^^^^^
  File "/home/inlinkff/virtualenv/linkedin-crm/3.11/lib/python3.11/site-packages/wtforms/fields/core.py", line 254, in _run_validation_chain
    validator(form, self)
  File "/home/inlinkff/linkedin-crm/app/controllers/forms.py", line 26, in validate_email
    if User.query.filter_by(email=field.data).first():
       ^^^^^^^^^^^^^^^^^^^^^^^^^^^^^^^^^^^^^^^^^^^^^^
  File "/home/inlinkff/virtualenv/linkedin-crm/3.11/lib64/python3.11/site-packages/sqlalchemy/orm/query.py", line 2759, in first
    return self.limit(1)._iter().first()  # type: ignore
           ^^^^^^^^^^^^^^^^^^^^^
  File "/home/inlinkff/virtualenv/linkedin-crm/3.11/lib64/python3.11/site-packages/sqlalchemy/orm/query.py", line 2858, in _iter
    result: Union[ScalarResult[_T], Result[_T]] = self.session.execute(
                                                  ^^^^^^^^^^^^^^^^^^^^^
  File "/home/inlinkff/virtualenv/linkedin-crm/3.11/lib64/python3.11/site-packages/sqlalchemy/orm/session.py", line 2365, in execute
    return self._execute_internal(
           ^^^^^^^^^^^^^^^^^^^^^^^
  File "/home/inlinkff/virtualenv/linkedin-crm/3.11/lib64/python3.11/site-packages/sqlalchemy/orm/session.py", line 2251, in _execute_internal
    result: Result[Any] = compile_state_cls.orm_execute_statement(
                          ^^^^^^^^^^^^^^^^^^^^^^^^^^^^^^^^^^^^^^^^
  File "/home/inlinkff/virtualenv/linkedin-crm/3.11/lib64/python3.11/site-packages/sqlalchemy/orm/context.py", line 306, in orm_execute_statement
    result = conn.execute(
             ^^^^^^^^^^^^^
  File "/home/inlinkff/virtualenv/linkedin-crm/3.11/lib64/python3.11/site-packages/sqlalchemy/engine/base.py", line 1416, in execute
    return meth(
           ^^^^^
  File "/home/inlinkff/virtualenv/linkedin-crm/3.11/lib64/python3.11/site-packages/sqlalchemy/sql/elements.py", line 523, in _execute_on_connection
    return connection._execute_clauseelement(
           ^^^^^^^^^^^^^^^^^^^^^^^^^^^^^^^^^^
  File "/home/inlinkff/virtualenv/linkedin-crm/3.11/lib64/python3.11/site-packages/sqlalchemy/engine/base.py", line 1638, in _execute_clauseelement
    ret = self._execute_context(
          ^^^^^^^^^^^^^^^^^^^^^^
  File "/home/inlinkff/virtualenv/linkedin-crm/3.11/lib64/python3.11/site-packages/sqlalchemy/engine/base.py", line 1843, in _execute_context
    return self._exec_single_context(
           ^^^^^^^^^^^^^^^^^^^^^^^^^^
  File "/home/inlinkff/virtualenv/linkedin-crm/3.11/lib64/python3.11/site-packages/sqlalchemy/engine/base.py", line 1983, in _exec_single_context
    self._handle_dbapi_exception(
  File "/home/inlinkff/virtualenv/linkedin-crm/3.11/lib64/python3.11/site-packages/sqlalchemy/engine/base.py", line 2352, in _handle_dbapi_exception
    raise sqlalchemy_exception.with_traceback(exc_info[2]) from e
  File "/home/inlinkff/virtualenv/linkedin-crm/3.11/lib64/python3.11/site-packages/sqlalchemy/engine/base.py", line 1964, in _exec_single_context
    self.dialect.do_execute(
  File "/home/inlinkff/virtualenv/linkedin-crm/3.11/lib64/python3.11/site-packages/sqlalchemy/engine/default.py", line 942, in do_execute
    cursor.execute(statement, parameters)
  File "/home/inlinkff/virtualenv/linkedin-crm/3.11/lib/python3.11/site-packages/pymysql/cursors.py", line 153, in execute
    result = self._query(query)
             ^^^^^^^^^^^^^^^^^^
  File "/home/inlinkff/virtualenv/linkedin-crm/3.11/lib/python3.11/site-packages/pymysql/cursors.py", line 322, in _query
    conn.query(q)
  File "/home/inlinkff/virtualenv/linkedin-crm/3.11/lib/python3.11/site-packages/pymysql/connections.py", line 558, in query
    self._affected_rows = self._read_query_result(unbuffered=unbuffered)
                          ^^^^^^^^^^^^^^^^^^^^^^^^^^^^^^^^^^^^^^^^^^^^^^
  File "/home/inlinkff/virtualenv/linkedin-crm/3.11/lib/python3.11/site-packages/pymysql/connections.py", line 822, in _read_query_result
    result.read()
  File "/home/inlinkff/virtualenv/linkedin-crm/3.11/lib/python3.11/site-packages/pymysql/connections.py", line 1200, in read
    first_packet = self.connection._read_packet()
                   ^^^^^^^^^^^^^^^^^^^^^^^^^^^^^^
  File "/home/inlinkff/virtualenv/linkedin-crm/3.11/lib/python3.11/site-packages/pymysql/connections.py", line 772, in _read_packet
    packet.raise_for_error()
  File "/home/inlinkff/virtualenv/linkedin-crm/3.11/lib/python3.11/site-packages/pymysql/protocol.py", line 221, in raise_for_error
    err.raise_mysql_exception(self._data)
  File "/home/inlinkff/virtualenv/linkedin-crm/3.11/lib/python3.11/site-packages/pymysql/err.py", line 143, in raise_mysql_exception
    raise errorclass(errno, errval)
sqlalchemy.exc.ProgrammingError: (pymysql.err.ProgrammingError) (1146, "Table 'inlinkff_crm.users' doesn't exist")
[SQL: SELECT users.id AS users_id, users.username AS users_username, users.email AS users_email, users.password_hash AS users_password_hash, users.created_at AS users_created_at 
FROM users 
WHERE users.email = %(email_1)s 
 LIMIT %(param_1)s]
[parameters: {'email_1': 'support@inlinkai.com', 'param_1': 1}]
(Background on this error at: https://sqlalche.me/e/20/f405)
[ERROR] [UID:2795][1369116] wsgiAppHandler pApp->start_response() return NULL.
Traceback (most recent call last):
  File "/home/inlinkff/virtualenv/linkedin-crm/3.11/lib64/python3.11/site-packages/sqlalchemy/engine/base.py", line 146, in __init__
    self._dbapi_connection = engine.raw_connection()
                             ^^^^^^^^^^^^^^^^^^^^^^^
  File "/home/inlinkff/virtualenv/linkedin-crm/3.11/lib64/python3.11/site-packages/sqlalchemy/engine/base.py", line 3298, in raw_connection
    return self.pool.connect()
           ^^^^^^^^^^^^^^^^^^^
  File "/home/inlinkff/virtualenv/linkedin-crm/3.11/lib64/python3.11/site-packages/sqlalchemy/pool/base.py", line 449, in connect
    return _ConnectionFairy._checkout(self)
           ^^^^^^^^^^^^^^^^^^^^^^^^^^^^^^^^
  File "/home/inlinkff/virtualenv/linkedin-crm/3.11/lib64/python3.11/site-packages/sqlalchemy/pool/base.py", line 1264, in _checkout
    fairy = _ConnectionRecord.checkout(pool)
            ^^^^^^^^^^^^^^^^^^^^^^^^^^^^^^^^
  File "/home/inlinkff/virtualenv/linkedin-crm/3.11/lib64/python3.11/site-packages/sqlalchemy/pool/base.py", line 713, in checkout
    rec = pool._do_get()
          ^^^^^^^^^^^^^^
  File "/home/inlinkff/virtualenv/linkedin-crm/3.11/lib64/python3.11/site-packages/sqlalchemy/pool/impl.py", line 179, in _do_get
    with util.safe_reraise():
  File "/home/inlinkff/virtualenv/linkedin-crm/3.11/lib64/python3.11/site-packages/sqlalchemy/util/langhelpers.py", line 146, in __exit__
    raise exc_value.with_traceback(exc_tb)
  File "/home/inlinkff/virtualenv/linkedin-crm/3.11/lib64/python3.11/site-packages/sqlalchemy/pool/impl.py", line 177, in _do_get
    return self._create_connection()
           ^^^^^^^^^^^^^^^^^^^^^^^^^
  File "/home/inlinkff/virtualenv/linkedin-crm/3.11/lib64/python3.11/site-packages/sqlalchemy/pool/base.py", line 390, in _create_connection
    return _ConnectionRecord(self)
           ^^^^^^^^^^^^^^^^^^^^^^^
  File "/home/inlinkff/virtualenv/linkedin-crm/3.11/lib64/python3.11/site-packages/sqlalchemy/pool/base.py", line 675, in __init__
    self.__connect()
  File "/home/inlinkff/virtualenv/linkedin-crm/3.11/lib64/python3.11/site-packages/sqlalchemy/pool/base.py", line 901, in __connect
    with util.safe_reraise():
  File "/home/inlinkff/virtualenv/linkedin-crm/3.11/lib64/python3.11/site-packages/sqlalchemy/util/langhelpers.py", line 146, in __exit__
    raise exc_value.with_traceback(exc_tb)
  File "/home/inlinkff/virtualenv/linkedin-crm/3.11/lib64/python3.11/site-packages/sqlalchemy/pool/base.py", line 897, in __connect
    self.dbapi_connection = connection = pool._invoke_creator(self)
                                         ^^^^^^^^^^^^^^^^^^^^^^^^^^
  File "/home/inlinkff/virtualenv/linkedin-crm/3.11/lib64/python3.11/site-packages/sqlalchemy/engine/create.py", line 646, in connect
    return dialect.connect(*cargs, **cparams)
           ^^^^^^^^^^^^^^^^^^^^^^^^^^^^^^^^^^
  File "/home/inlinkff/virtualenv/linkedin-crm/3.11/lib64/python3.11/site-packages/sqlalchemy/engine/default.py", line 622, in connect
    return self.loaded_dbapi.connect(*cargs, **cparams)
           ^^^^^^^^^^^^^^^^^^^^^^^^^^^^^^^^^^^^^^^^^^^^
  File "/home/inlinkff/virtualenv/linkedin-crm/3.11/lib/python3.11/site-packages/pymysql/connections.py", line 358, in __init__
    self.connect()
  File "/home/inlinkff/virtualenv/linkedin-crm/3.11/lib/python3.11/site-packages/pymysql/connections.py", line 664, in connect
    self._request_authentication()
  File "/home/inlinkff/virtualenv/linkedin-crm/3.11/lib/python3.11/site-packages/pymysql/connections.py", line 954, in _request_authentication
    auth_packet = self._read_packet()
                  ^^^^^^^^^^^^^^^^^^^
  File "/home/inlinkff/virtualenv/linkedin-crm/3.11/lib/python3.11/site-packages/pymysql/connections.py", line 772, in _read_packet
    packet.raise_for_error()
  File "/home/inlinkff/virtualenv/linkedin-crm/3.11/lib/python3.11/site-packages/pymysql/protocol.py", line 221, in raise_for_error
    err.raise_mysql_exception(self._data)
  File "/home/inlinkff/virtualenv/linkedin-crm/3.11/lib/python3.11/site-packages/pymysql/err.py", line 143, in raise_mysql_exception
    raise errorclass(errno, errval)
pymysql.err.OperationalError: (1044, "Access denied for user 'inlinkff_admin'@'localhost' to database 'linkedin_crm'")

The above exception was the direct cause of the following exception:

Traceback (most recent call last):
  File "/home/inlinkff/virtualenv/linkedin-crm/3.11/lib/python3.11/site-packages/flask/app.py", line 2213, in __call__
    return self.wsgi_app(environ, start_response)
           ^^^^^^^^^^^^^^^^^^^^^^^^^^^^^^^^^^^^^^
  File "/home/inlinkff/virtualenv/linkedin-crm/3.11/lib/python3.11/site-packages/flask/app.py", line 2193, in wsgi_app
    response = self.handle_exception(e)
               ^^^^^^^^^^^^^^^^^^^^^^^^
  File "/home/inlinkff/virtualenv/linkedin-crm/3.11/lib/python3.11/site-packages/flask_cors/extension.py", line 176, in wrapped_function
    return cors_after_request(app.make_response(f(*args, **kwargs)))
                                                ^^^^^^^^^^^^^^^^^^
  File "/home/inlinkff/virtualenv/linkedin-crm/3.11/lib/python3.11/site-packages/flask/app.py", line 2190, in wsgi_app
    response = self.full_dispatch_request()
               ^^^^^^^^^^^^^^^^^^^^^^^^^^^^
  File "/home/inlinkff/virtualenv/linkedin-crm/3.11/lib/python3.11/site-packages/flask/app.py", line 1486, in full_dispatch_request
    rv = self.handle_user_exception(e)
         ^^^^^^^^^^^^^^^^^^^^^^^^^^^^^
  File "/home/inlinkff/virtualenv/linkedin-crm/3.11/lib/python3.11/site-packages/flask_cors/extension.py", line 176, in wrapped_function
    return cors_after_request(app.make_response(f(*args, **kwargs)))
                                                ^^^^^^^^^^^^^^^^^^
  File "/home/inlinkff/virtualenv/linkedin-crm/3.11/lib/python3.11/site-packages/flask/app.py", line 1484, in full_dispatch_request
    rv = self.dispatch_request()
         ^^^^^^^^^^^^^^^^^^^^^^^
  File "/home/inlinkff/virtualenv/linkedin-crm/3.11/lib/python3.11/site-packages/flask/app.py", line 1469, in dispatch_request
    return self.ensure_sync(self.view_functions[rule.endpoint])(**view_args)
           ^^^^^^^^^^^^^^^^^^^^^^^^^^^^^^^^^^^^^^^^^^^^^^^^^^^^^^^^^^^^^^^^^
  File "/home/inlinkff/linkedin-crm/app/controllers/auth.py", line 38, in register
    if form.validate_on_submit():
       ^^^^^^^^^^^^^^^^^^^^^^^^^
  File "/home/inlinkff/virtualenv/linkedin-crm/3.11/lib/python3.11/site-packages/flask_wtf/form.py", line 86, in validate_on_submit
    return self.is_submitted() and self.validate(extra_validators=extra_validators)
                                   ^^^^^^^^^^^^^^^^^^^^^^^^^^^^^^^^^^^^^^^^^^^^^^^^
  File "/home/inlinkff/virtualenv/linkedin-crm/3.11/lib/python3.11/site-packages/wtforms/form.py", line 330, in validate
    return super().validate(extra)
           ^^^^^^^^^^^^^^^^^^^^^^^
  File "/home/inlinkff/virtualenv/linkedin-crm/3.11/lib/python3.11/site-packages/wtforms/form.py", line 147, in validate
    if not field.validate(self, extra):
           ^^^^^^^^^^^^^^^^^^^^^^^^^^^
  File "/home/inlinkff/virtualenv/linkedin-crm/3.11/lib/python3.11/site-packages/wtforms/fields/core.py", line 234, in validate
    stop_validation = self._run_validation_chain(form, chain)
                      ^^^^^^^^^^^^^^^^^^^^^^^^^^^^^^^^^^^^^^^
  File "/home/inlinkff/virtualenv/linkedin-crm/3.11/lib/python3.11/site-packages/wtforms/fields/core.py", line 254, in _run_validation_chain
    validator(form, self)
  File "/home/inlinkff/linkedin-crm/app/controllers/forms.py", line 26, in validate_email
    if User.query.filter_by(email=field.data).first():
       ^^^^^^^^^^^^^^^^^^^^^^^^^^^^^^^^^^^^^^^^^^^^^^
  File "/home/inlinkff/virtualenv/linkedin-crm/3.11/lib64/python3.11/site-packages/sqlalchemy/orm/query.py", line 2759, in first
    return self.limit(1)._iter().first()  # type: ignore
           ^^^^^^^^^^^^^^^^^^^^^
  File "/home/inlinkff/virtualenv/linkedin-crm/3.11/lib64/python3.11/site-packages/sqlalchemy/orm/query.py", line 2858, in _iter
    result: Union[ScalarResult[_T], Result[_T]] = self.session.execute(
                                                  ^^^^^^^^^^^^^^^^^^^^^
  File "/home/inlinkff/virtualenv/linkedin-crm/3.11/lib64/python3.11/site-packages/sqlalchemy/orm/session.py", line 2365, in execute
    return self._execute_internal(
           ^^^^^^^^^^^^^^^^^^^^^^^
  File "/home/inlinkff/virtualenv/linkedin-crm/3.11/lib64/python3.11/site-packages/sqlalchemy/orm/session.py", line 2241, in _execute_internal
    conn = self._connection_for_bind(bind)
           ^^^^^^^^^^^^^^^^^^^^^^^^^^^^^^^
  File "/home/inlinkff/virtualenv/linkedin-crm/3.11/lib64/python3.11/site-packages/sqlalchemy/orm/session.py", line 2110, in _connection_for_bind
    return trans._connection_for_bind(engine, execution_options)
           ^^^^^^^^^^^^^^^^^^^^^^^^^^^^^^^^^^^^^^^^^^^^^^^^^^^^^
  File "<string>", line 2, in _connection_for_bind
  File "/home/inlinkff/virtualenv/linkedin-crm/3.11/lib64/python3.11/site-packages/sqlalchemy/orm/state_changes.py", line 139, in _go
    ret_value = fn(self, *arg, **kw)
                ^^^^^^^^^^^^^^^^^^^^
  File "/home/inlinkff/virtualenv/linkedin-crm/3.11/lib64/python3.11/site-packages/sqlalchemy/orm/session.py", line 1189, in _connection_for_bind
    conn = bind.connect()
           ^^^^^^^^^^^^^^
  File "/home/inlinkff/virtualenv/linkedin-crm/3.11/lib64/python3.11/site-packages/sqlalchemy/engine/base.py", line 3274, in connect
    return self._connection_cls(self)
           ^^^^^^^^^^^^^^^^^^^^^^^^^^
  File "/home/inlinkff/virtualenv/linkedin-crm/3.11/lib64/python3.11/site-packages/sqlalchemy/engine/base.py", line 148, in __init__
    Connection._handle_dbapi_exception_noconnection(
  File "/home/inlinkff/virtualenv/linkedin-crm/3.11/lib64/python3.11/site-packages/sqlalchemy/engine/base.py", line 2439, in _handle_dbapi_exception_noconnection
    raise sqlalchemy_exception.with_traceback(exc_info[2]) from e
  File "/home/inlinkff/virtualenv/linkedin-crm/3.11/lib64/python3.11/site-packages/sqlalchemy/engine/base.py", line 146, in __init__
    self._dbapi_connection = engine.raw_connection()
                             ^^^^^^^^^^^^^^^^^^^^^^^
  File "/home/inlinkff/virtualenv/linkedin-crm/3.11/lib64/python3.11/site-packages/sqlalchemy/engine/base.py", line 3298, in raw_connection
    return self.pool.connect()
           ^^^^^^^^^^^^^^^^^^^
  File "/home/inlinkff/virtualenv/linkedin-crm/3.11/lib64/python3.11/site-packages/sqlalchemy/pool/base.py", line 449, in connect
    return _ConnectionFairy._checkout(self)
           ^^^^^^^^^^^^^^^^^^^^^^^^^^^^^^^^
  File "/home/inlinkff/virtualenv/linkedin-crm/3.11/lib64/python3.11/site-packages/sqlalchemy/pool/base.py", line 1264, in _checkout
    fairy = _ConnectionRecord.checkout(pool)
            ^^^^^^^^^^^^^^^^^^^^^^^^^^^^^^^^
  File "/home/inlinkff/virtualenv/linkedin-crm/3.11/lib64/python3.11/site-packages/sqlalchemy/pool/base.py", line 713, in checkout
    rec = pool._do_get()
          ^^^^^^^^^^^^^^
  File "/home/inlinkff/virtualenv/linkedin-crm/3.11/lib64/python3.11/site-packages/sqlalchemy/pool/impl.py", line 179, in _do_get
    with util.safe_reraise():
  File "/home/inlinkff/virtualenv/linkedin-crm/3.11/lib64/python3.11/site-packages/sqlalchemy/util/langhelpers.py", line 146, in __exit__
    raise exc_value.with_traceback(exc_tb)
  File "/home/inlinkff/virtualenv/linkedin-crm/3.11/lib64/python3.11/site-packages/sqlalchemy/pool/impl.py", line 177, in _do_get
    return self._create_connection()
           ^^^^^^^^^^^^^^^^^^^^^^^^^
  File "/home/inlinkff/virtualenv/linkedin-crm/3.11/lib64/python3.11/site-packages/sqlalchemy/pool/base.py", line 390, in _create_connection
    return _ConnectionRecord(self)
           ^^^^^^^^^^^^^^^^^^^^^^^
  File "/home/inlinkff/virtualenv/linkedin-crm/3.11/lib64/python3.11/site-packages/sqlalchemy/pool/base.py", line 675, in __init__
    self.__connect()
  File "/home/inlinkff/virtualenv/linkedin-crm/3.11/lib64/python3.11/site-packages/sqlalchemy/pool/base.py", line 901, in __connect
    with util.safe_reraise():
  File "/home/inlinkff/virtualenv/linkedin-crm/3.11/lib64/python3.11/site-packages/sqlalchemy/util/langhelpers.py", line 146, in __exit__
    raise exc_value.with_traceback(exc_tb)
  File "/home/inlinkff/virtualenv/linkedin-crm/3.11/lib64/python3.11/site-packages/sqlalchemy/pool/base.py", line 897, in __connect
    self.dbapi_connection = connection = pool._invoke_creator(self)
                                         ^^^^^^^^^^^^^^^^^^^^^^^^^^
  File "/home/inlinkff/virtualenv/linkedin-crm/3.11/lib64/python3.11/site-packages/sqlalchemy/engine/create.py", line 646, in connect
    return dialect.connect(*cargs, **cparams)
           ^^^^^^^^^^^^^^^^^^^^^^^^^^^^^^^^^^
  File "/home/inlinkff/virtualenv/linkedin-crm/3.11/lib64/python3.11/site-packages/sqlalchemy/engine/default.py", line 622, in connect
    return self.loaded_dbapi.connect(*cargs, **cparams)
           ^^^^^^^^^^^^^^^^^^^^^^^^^^^^^^^^^^^^^^^^^^^^
  File "/home/inlinkff/virtualenv/linkedin-crm/3.11/lib/python3.11/site-packages/pymysql/connections.py", line 358, in __init__
    self.connect()
  File "/home/inlinkff/virtualenv/linkedin-crm/3.11/lib/python3.11/site-packages/pymysql/connections.py", line 664, in connect
    self._request_authentication()
  File "/home/inlinkff/virtualenv/linkedin-crm/3.11/lib/python3.11/site-packages/pymysql/connections.py", line 954, in _request_authentication
    auth_packet = self._read_packet()
                  ^^^^^^^^^^^^^^^^^^^
  File "/home/inlinkff/virtualenv/linkedin-crm/3.11/lib/python3.11/site-packages/pymysql/connections.py", line 772, in _read_packet
    packet.raise_for_error()
  File "/home/inlinkff/virtualenv/linkedin-crm/3.11/lib/python3.11/site-packages/pymysql/protocol.py", line 221, in raise_for_error
    err.raise_mysql_exception(self._data)
  File "/home/inlinkff/virtualenv/linkedin-crm/3.11/lib/python3.11/site-packages/pymysql/err.py", line 143, in raise_mysql_exception
    raise errorclass(errno, errval)
sqlalchemy.exc.OperationalError: (pymysql.err.OperationalError) (1044, "Access denied for user 'inlinkff_admin'@'localhost' to database 'linkedin_crm'")
(Background on this error at: https://sqlalche.me/e/20/e3q8)
Extension directory: /home/inlinkff/linkedin-crm/app/../extension
Files in directory: ['content.js', 'popup.html', 'manifest.json', 'icons', 'popup.js']
Adding file to zip: content.js
Adding file to zip: popup.html
Adding file to zip: manifest.json
Adding file to zip: popup.js
Adding file to zip: icons/icon48.png
Adding file to zip: icons/icon128.png
Adding file to zip: icons/icon16.png
